Workbook
Name Action: 'Transaction Log'!$D$2:$D$159
Name Amount: 'Transaction Log'!$J$2:$J$159
Name broker_fee: 'Transaction Log'!$P$2
Name Cashflow: 'Transaction Log'!$M$2:$M$159
Name Date: 'Transaction Log'!$A$2:$A$159
Name Dividend_per_Share: 'Transaction Log'!$I$2:$I$159
Name exchange_fee: 'Transaction Log'!$P$1
Name Lot: 'Transaction Log'!$E$2:$E$159
Name Net_Amount: 'Transaction Log'!$L$2:$L$159
Name Position_Change: 'Transaction Log'!$F$2:$F$159
Name Price: 'Transaction Log'!$G$2:$G$159
Name Slicer_Growth_Percentage: #N/A
Name Slicer_Stock_Ticker: #N/A
Name Stock_Tickers: 'Transaction Log'!$C$2:$C$159
Name Total_Fee: 'Transaction Log'!$K$2:$K$159
Name Transaction_ID: 'Transaction Log'!$B$2:$B$159

Sheet Dashboard

Sheet Transaction Log
A1: Date | B1: Transaction ID | C1: Stock Tickers | D1: Action | E1: Lot | F1: Position Change | G1: Price | H1: Weighted Average Price | I1: Dividend per Share | J1: Amount | K1: Total Fee | L1: Net Amount | M1: Cashflow | O1: Exchange Fee | P1: 0.000433
A2: 45294 | B2: ="TX"&TEXT(ROW()-1,"0000") -> TX0001 | D2: Deposit | F2: {=_xlfn.IFS(Table1[[#This Row],[Action]]="Buy",Table1[[#This Row],[Lot ]],Table1[[#This Row],[Action]]="Sell",-Table1[[#This Row],[Lot ]],Table1[[#This Row],[Action]]="Dividend",0,TRUE,"")} | H2: {=IF(OR(Table1[[#This Row],[Stock Tickers]]="",Table1[[#This Row],[Action]]="Dividend"), "",IF(Table1[[#This Row],[Action]]="Buy",(SUMIFS($L2:L$2, $C2:C$2,Table1[[#This Row],[Stock Tickers]], $D2:D$2, "Buy") + Table1[[#This Row],[Amount]]) / ((SUMIFS($E2:E$2, $C2:C$2,Table1[[#This Row],[Stock Tickers]], $D2:D$2, "Buy") + Table1[[#This Row],[Lot ]])*100),LOOKUP(2, 1/($C2:C$2=Table1[[#This Row],[Stock Tickers]]), $G2:G$2)))} | J2: 100000000 | L2: =SUM(Table1[[#This Row],[Amount]]:Table1[[#This Row],[Total Fee]]) -> 100000000 | M2: =IF(OR(Table1[[#This Row],[Action]]="Buy",Table1[[#This Row],[Action]]="Withdraw"),-Table1[[#This Row],[Net Amount]],Table1[[#This Row],[Net Amount]]) -> 100000000 | O2: Broker Fee | P2: 0.0015
A3: 45296 | B3: ="TX"&TEXT(ROW()-1,"0000") -> TX0002 | C3: BBRI | D3: Buy | E3: 25 | F3: {=_xlfn.IFS(Table1[[#This Row],[Action]]="Buy",Table1[[#This Row],[Lot ]],Table1[[#This Row],[Action]]="Sell",-Table1[[#This Row],[Lot ]],Table1[[#This Row],[Action]]="Dividend",0,TRUE,"")} -> 25 | G3: 3800 | H3: {=IF(OR(Table1[[#This Row],[Stock Tickers]]="",Table1[[#This Row],[Action]]="Dividend"), "",IF(Table1[[#This Row],[Action]]="Buy",(SUMIFS($L$2:L3, $C$2:C3,Table1[[#This Row],[Stock Tickers]], $D$2:D3, "Buy") + Table1[[#This Row],[Amount]]) / ((SUMIFS($E$2:E3, $C$2:C3,Table1[[#This Row],[Stock Tickers]], $D$2:D3, "Buy") + Table1[[#This Row],[Lot ]])*100),LOOKUP(2, 1/($C$2:C3=Table1[[#This Row],[Stock Tickers]]), $G$2:G3)))} -> 3803.6727 | J3: =(Table1[[#This Row],[Lot ]]*100)*IF(Table1[[#This Row],[Action]]="Dividend",Table1[[#This Row],[Dividend per Share]],Table1[[#This Row],[Price]]) -> 9500000 | K3: =(exchange_fee+broker_fee)*J3 -> 18363.5 | L3: =SUM(Table1[[#This Row],[Amount]]:Table1[[#This Row],[Total Fee]]) -> 9518363.5 | M3: =IF(OR(Table1[[#This Row],[Action]]="Buy",Table1[[#This Row],[Action]]="Withdraw"),-Table1[[#This Row],[Net Amount]],Table1[[#This Row],[Net Amount]]) -> -9518363.5
A4: 45301 | B4: ="TX"&TEXT(ROW()-1,"0000") -> TX0003 | C4: TLKM | D4: Buy | E4: 42 | F4: {=_xlfn.IFS(Table1[[#This Row],[Action]]="Buy",Table1[[#This Row],[Lot ]],Table1[[#This Row],[Action]]="Sell",-Table1[[#This Row],[Lot ]],Table1[[#This Row],[Action]]="Dividend",0,TRUE,"")} -> 42 | G4: 3050 | H4: {=IF(OR(Table1[[#This Row],[Stock Tickers]]="",Table1[[#This Row],[Action]]="Dividend"), "",IF(Table1[[#This Row],[Action]]="Buy",(SUMIFS($L$2:L4, $C$2:C4,Table1[[#This Row],[Stock Tickers]], $D$2:D4, "Buy") + Table1[[#This Row],[Amount]]) / ((SUMIFS($E$2:E4, $C$2:C4,Table1[[#This Row],[Stock Tickers]], $D$2:D4, "Buy") + Table1[[#This Row],[Lot ]])*100),LOOKUP(2, 1/($C$2:C4=Table1[[#This Row],[Stock Tickers]]), $G$2:G4)))} -> 3052.9478 | J4: =(Table1[[#This Row],[Lot ]]*100)*IF(Table1[[#This Row],[Action]]="Dividend",Table1[[#This Row],[Dividend per Share]],Table1[[#This Row],[Price]]) -> 12810000 | K4: =(exchange_fee+broker_fee)*J4 -> 24761.73 | L4: =SUM(Table1[[#This Row],[Amount]]:Table1[[#This Row],[Total Fee]]) -> 12834762 | M4: =IF(OR(Table1[[#This Row],[Action]]="Buy",Table1[[#This Row],[Action]]="Withdraw"),-Table1[[#This Row],[Net Amount]],Table1[[#This Row],[Net Amount]]) -> -12834762
A5: 45309 | B5: ="TX"&TEXT(ROW()-1,"0000") -> TX0004 | C5: ADRO | D5: Buy | E5: 21 | F5: {=_xlfn.IFS(Table1[[#This Row],[Action]]="Buy",Table1[[#This Row],[Lot ]],Table1[[#This Row],[Action]]="Sell",-Table1[[#This Row],[Lot ]],Table1[[#This Row],[Action]]="Dividend",0,TRUE,"")} -> 21 | G5: 2530 | H5: {=IF(OR(Table1[[#This Row],[Stock Tickers]]="",Table1[[#This Row],[Action]]="Dividend"), "",IF(Table1[[#This Row],[Action]]="Buy",(SUMIFS($L$2:L5, $C$2:C5,Table1[[#This Row],[Stock Tickers]], $D$2:D5, "Buy") + Table1[[#This Row],[Amount]]) / ((SUMIFS($E$2:E5, $C$2:C5,Table1[[#This Row],[Stock Tickers]], $D$2:D5, "Buy") + Table1[[#This Row],[Lot ]])*100),LOOKUP(2, 1/($C$2:C5=Table1[[#This Row],[Stock Tickers]]), $G$2:G5)))} -> 2532.4452 | J5: =(Table1[[#This Row],[Lot ]]*100)*IF(Table1[[#This Row],[Action]]="Dividend",Table1[[#This Row],[Dividend per Share]],Table1[[#This Row],[Price]]) -> 5313000 | K5: =(exchange_fee+broker_fee)*J5 -> 10270.029 | L5: =SUM(Table1[[#This Row],[Amount]]:Table1[[#This Row],[Total Fee]]) -> 5323270 | M5: =IF(OR(Table1[[#This Row],[Action]]="Buy",Table1[[#This Row],[Action]]="Withdraw"),-Table1[[#This Row],[Net Amount]],Table1[[#This Row],[Net Amount]]) -> -5323270
A6: 45324 | B6: ="TX"&TEXT(ROW()-1,"0000") -> TX0005 | C6: BBCA | D6: Buy | E6: 7 | F6: {=_xlfn.IFS(Table1[[#This Row],[Action]]="Buy",Table1[[#This Row],[Lot ]],Table1[[#This Row],[Action]]="Sell",-Table1[[#This Row],[Lot ]],Table1[[#This Row],[Action]]="Dividend",0,TRUE,"")} -> 7 | G6: 7560 | H6: {=IF(OR(Table1[[#This Row],[Stock Tickers]]="",Table1[[#This Row],[Action]]="Dividend"), "",IF(Table1[[#This Row],[Action]]="Buy",(SUMIFS($L$2:L6, $C$2:C6,Table1[[#This Row],[Stock Tickers]], $D$2:D6, "Buy") + Table1[[#This Row],[Amount]]) / ((SUMIFS($E$2:E6, $C$2:C6,Table1[[#This Row],[Stock Tickers]], $D$2:D6, "Buy") + Table1[[#This Row],[Lot ]])*100),LOOKUP(2, 1/($C$2:C6=Table1[[#This Row],[Stock Tickers]]), $G$2:G6)))} -> 7567.3067 | J6: =(Table1[[#This Row],[Lot ]]*100)*IF(Table1[[#This Row],[Action]]="Dividend",Table1[[#This Row],[Dividend per Share]],Table1[[#This Row],[Price]]) -> 5292000 | K6: =(exchange_fee+broker_fee)*J6 -> 10229.436 | L6: =SUM(Table1[[#This Row],[Amount]]:Table1[[#This Row],[Total Fee]]) -> 5302229.4 | M6: =IF(OR(Table1[[#This Row],[Action]]="Buy",Table1[[#This Row],[Action]]="Withdraw"),-Table1[[#This Row],[Net Amount]],Table1[[#This Row],[Net Amount]]) -> -5302229.4
A7: 45329 | B7: ="TX"&TEXT(ROW()-1,"0000") -> TX0006 | C7: ASII | D7: Buy | E7: 32 | F7: {=_xlfn.IFS(Table1[[#This Row],[Action]]="Buy",Table1[[#This Row],[Lot ]],Table1[[#This Row],[Action]]="Sell",-Table1[[#This Row],[Lot ]],Table1[[#This Row],[Action]]="Dividend",0,TRUE,"")} -> 32 | G7: 5100 | H7: {=IF(OR(Table1[[#This Row],[Stock Tickers]]="",Table1[[#This Row],[Action]]="Dividend"), "",IF(Table1[[#This Row],[Action]]="Buy",(SUMIFS($L$2:L7, $C$2:C7,Table1[[#This Row],[Stock Tickers]], $D$2:D7, "Buy") + Table1[[#This Row],[Amount]]) / ((SUMIFS($E$2:E7, $C$2:C7,Table1[[#This Row],[Stock Tickers]], $D$2:D7, "Buy") + Table1[[#This Row],[Lot ]])*100),LOOKUP(2, 1/($C$2:C7=Table1[[#This Row],[Stock Tickers]]), $G$2:G7)))} -> 5104.9291 | J7: =(Table1[[#This Row],[Lot ]]*100)*IF(Table1[[#This Row],[Action]]="Dividend",Table1[[#This Row],[Dividend per Share]],Table1[[#This Row],[Price]]) -> 16320000 | K7: =(exchange_fee+broker_fee)*J7 -> 31546.56 | L7: =SUM(Table1[[#This Row],[Amount]]:Table1[[#This Row],[Total Fee]]) -> 16351547 | M7: =IF(OR(Table1[[#This Row],[Action]]="Buy",Table1[[#This Row],[Action]]="Withdraw"),-Table1[[#This Row],[Net Amount]],Table1[[#This Row],[Net Amount]]) -> -16351547
A8: 45336 | B8: ="TX"&TEXT(ROW()-1,"0000") -> TX0007 | C8: TLKM | D8: Dividend | E8: 42 | F8: {=_xlfn.IFS(Table1[[#This Row],[Action]]="Buy",Table1[[#This Row],[Lot ]],Table1[[#This Row],[Action]]="Sell",-Table1[[#This Row],[Lot ]],Table1[[#This Row],[Action]]="Dividend",0,TRUE,"")} -> 0 | H8: {=IF(OR(Table1[[#This Row],[Stock Tickers]]="",Table1[[#This Row],[Action]]="Dividend"), "",IF(Table1[[#This Row],[Action]]="Buy",(SUMIFS($L$2:L8, $C$2:C8,Table1[[#This Row],[Stock Tickers]], $D$2:D8, "Buy") + Table1[[#This Row],[Amount]]) / ((SUMIFS($E$2:E8, $C$2:C8,Table1[[#This Row],[Stock Tickers]], $D$2:D8, "Buy") + Table1[[#This Row],[Lot ]])*100),LOOKUP(2, 1/($C$2:C8=Table1[[#This Row],[Stock Tickers]]), $G$2:G8)))} | I8: 178 | J8: =(Table1[[#This Row],[Lot ]]*100)*IF(Table1[[#This Row],[Action]]="Dividend",Table1[[#This Row],[Dividend per Share]],Table1[[#This Row],[Price]]) -> 747600 | L8: =SUM(Table1[[#This Row],[Amount]]:Table1[[#This Row],[Total Fee]]) -> 747600 | M8: =IF(OR(Table1[[#This Row],[Action]]="Buy",Table1[[#This Row],[Action]]="Withdraw"),-Table1[[#This Row],[Net Amount]],Table1[[#This Row],[Net Amount]]) -> 747600
A9: 45342 | B9: ="TX"&TEXT(ROW()-1,"0000") -> TX0008 | C9: ADRO | D9: Buy | E9: 38 | F9: {=_xlfn.IFS(Table1[[#This Row],[Action]]="Buy",Table1[[#This Row],[Lot ]],Table1[[#This Row],[Action]]="Sell",-Table1[[#This Row],[Lot ]],Table1[[#This Row],[Action]]="Dividend",0,TRUE,"")} -> 38 | G9: 2910 | H9: {=IF(OR(Table1[[#This Row],[Stock Tickers]]="",Table1[[#This Row],[Action]]="Dividend"), "",IF(Table1[[#This Row],[Action]]="Buy",(SUMIFS($L$2:L9, $C$2:C9,Table1[[#This Row],[Stock Tickers]], $D$2:D9, "Buy") + Table1[[#This Row],[Amount]]) / ((SUMIFS($E$2:E9, $C$2:C9,Table1[[#This Row],[Stock Tickers]], $D$2:D9, "Buy") + Table1[[#This Row],[Lot ]])*100),LOOKUP(2, 1/($C$2:C9=Table1[[#This Row],[Stock Tickers]]), $G$2:G9)))} -> 2830.9943 | J9: =(Table1[[#This Row],[Lot ]]*100)*IF(Table1[[#This Row],[Action]]="Dividend",Table1[[#This Row],[Dividend per Share]],Table1[[#This Row],[Price]]) -> 11058000 | K9: =(exchange_fee+broker_fee)*J9 -> 21375.114 | L9: =SUM(Table1[[#This Row],[Amount]]:Table1[[#This Row],[Total Fee]]) -> 11079375 | M9: =IF(OR(Table1[[#This Row],[Action]]="Buy",Table1[[#This Row],[Action]]="Withdraw"),-Table1[[#This Row],[Net Amount]],Table1[[#This Row],[Net Amount]]) -> -11079375
A10: 45350 | B10: ="TX"&TEXT(ROW()-1,"0000") -> TX0009 | D10: Deposit | F10: {=_xlfn.IFS(Table1[[#This Row],[Action]]="Buy",Table1[[#This Row],[Lot ]],Table1[[#This Row],[Action]]="Sell",-Table1[[#This Row],[Lot ]],Table1[[#This Row],[Action]]="Dividend",0,TRUE,"")} | H10: {=IF(OR(Table1[[#This Row],[Stock Tickers]]="",Table1[[#This Row],[Action]]="Dividend"), "",IF(Table1[[#This Row],[Action]]="Buy",(SUMIFS($L$2:L10, $C$2:C10,Table1[[#This Row],[Stock Tickers]], $D$2:D10, "Buy") + Table1[[#This Row],[Amount]]) / ((SUMIFS($E$2:E10, $C$2:C10,Table1[[#This Row],[Stock Tickers]], $D$2:D10, "Buy") + Table1[[#This Row],[Lot ]])*100),LOOKUP(2, 1/($C$2:C10=Table1[[#This Row],[Stock Tickers]]), $G$2:G10)))} | J10: 65000000 | L10: =SUM(Table1[[#This Row],[Amount]]:Table1[[#This Row],[Total Fee]]) -> 65000000 | M10: =IF(OR(Table1[[#This Row],[Action]]="Buy",Table1[[#This Row],[Action]]="Withdraw"),-Table1[[#This Row],[Net Amount]],Table1[[#This Row],[Net Amount]]) -> 65000000
A11: 45354 | B11: ="TX"&TEXT(ROW()-1,"0000") -> TX0010 | C11: ITMG | D11: Buy | E11: 10 | F11: {=_xlfn.IFS(Table1[[#This Row],[Action]]="Buy",Table1[[#This Row],[Lot ]],Table1[[#This Row],[Action]]="Sell",-Table1[[#This Row],[Lot ]],Table1[[#This Row],[Action]]="Dividend",0,TRUE,"")} -> 10 | G11: 30000 | H11: {=IF(OR(Table1[[#This Row],[Stock Tickers]]="",Table1[[#This Row],[Action]]="Dividend"), "",IF(Table1[[#This Row],[Action]]="Buy",(SUMIFS($L$2:L11, $C$2:C11,Table1[[#This Row],[Stock Tickers]], $D$2:D11, "Buy") + Table1[[#This Row],[Amount]]) / ((SUMIFS($E$2:E11, $C$2:C11,Table1[[#This Row],[Stock Tickers]], $D$2:D11, "Buy") + Table1[[#This Row],[Lot ]])*100),LOOKUP(2, 1/($C$2:C11=Table1[[#This Row],[Stock Tickers]]), $G$2:G11)))} -> 30028.995 | J11: =(Table1[[#This Row],[Lot ]]*100)*IF(Table1[[#This Row],[Action]]="Dividend",Table1[[#This Row],[Dividend per Share]],Table1[[#This Row],[Price]]) -> 30000000 | K11: =(exchange_fee+broker_fee)*J11 -> 57990 | L11: =SUM(Table1[[#This Row],[Amount]]:Table1[[#This Row],[Total Fee]]) -> 30057990 | M11: =IF(OR(Table1[[#This Row],[Action]]="Buy",Table1[[#This Row],[Action]]="Withdraw"),-Table1[[#This Row],[Net Amount]],Table1[[#This Row],[Net Amount]]) -> -30057990
A12: 45356 | B12: ="TX"&TEXT(ROW()-1,"0000") -> TX0011 | C12: BBRI | D12: Buy | E12: 10 | F12: {=_xlfn.IFS(Table1[[#This Row],[Action]]="Buy",Table1[[#This Row],[Lot ]],Table1[[#This Row],[Action]]="Sell",-Table1[[#This Row],[Lot ]],Table1[[#This Row],[Action]]="Dividend",0,TRUE,"")} -> 10 | G12: 2990 | H12: {=IF(OR(Table1[[#This Row],[Stock Tickers]]="",Table1[[#This Row],[Action]]="Dividend"), "",IF(Table1[[#This Row],[Action]]="Buy",(SUMIFS($L$2:L12, $C$2:C12,Table1[[#This Row],[Stock Tickers]], $D$2:D12, "Buy") + Table1[[#This Row],[Amount]]) / ((SUMIFS($E$2:E12, $C$2:C12,Table1[[#This Row],[Stock Tickers]], $D$2:D12, "Buy") + Table1[[#This Row],[Lot ]])*100),LOOKUP(2, 1/($C$2:C12=Table1[[#This Row],[Stock Tickers]]), $G$2:G12)))} -> 3445.3651 | J12: =(Table1[[#This Row],[Lot ]]*100)*IF(Table1[[#This Row],[Action]]="Dividend",Table1[[#This Row],[Dividend per Share]],Table1[[#This Row],[Price]]) -> 2990000 | K12: =(exchange_fee+broker_fee)*J12 -> 5779.67 | L12: =SUM(Table1[[#This Row],[Amount]]:Table1[[#This Row],[Total Fee]]) -> 2995779.7 | M12: =IF(OR(Table1[[#This Row],[Action]]="Buy",Table1[[#This Row],[Action]]="Withdraw"),-Table1[[#This Row],[Net Amount]],Table1[[#This Row],[Net Amount]]) -> -2995779.7
A13: 45366 | B13: ="TX"&TEXT(ROW()-1,"0000") -> TX0012 | C13: BBCA | D13: Buy | E13: 7 | F13: {=_xlfn.IFS(Table1[[#This Row],[Action]]="Buy",Table1[[#This Row],[Lot ]],Table1[[#This Row],[Action]]="Sell",-Table1[[#This Row],[Lot ]],Table1[[#This Row],[Action]]="Dividend",0,TRUE,"")} -> 7 | G13: 7200 | H13: {=IF(OR(Table1[[#This Row],[Stock Tickers]]="",Table1[[#This Row],[Action]]="Dividend"), "",IF(Table1[[#This Row],[Action]]="Buy",(SUMIFS($L$2:L13, $C$2:C13,Table1[[#This Row],[Stock Tickers]], $D$2:D13, "Buy") + Table1[[#This Row],[Amount]]) / ((SUMIFS($E$2:E13, $C$2:C13,Table1[[#This Row],[Stock Tickers]], $D$2:D13, "Buy") + Table1[[#This Row],[Lot ]])*100),LOOKUP(2, 1/($C$2:C13=Table1[[#This Row],[Stock Tickers]]), $G$2:G13)))} -> 7329.5104 | J13: =(Table1[[#This Row],[Lot ]]*100)*IF(Table1[[#This Row],[Action]]="Dividend",Table1[[#This Row],[Dividend per Share]],Table1[[#This Row],[Price]]) -> 5040000 | K13: =(exchange_fee+broker_fee)*J13 -> 9742.32 | L13: =SUM(Table1[[#This Row],[Amount]]:Table1[[#This Row],[Total Fee]]) -> 5049742.3 | M13: =IF(OR(Table1[[#This Row],[Action]]="Buy",Table1[[#This Row],[Action]]="Withdraw"),-Table1[[#This Row],[Net Amount]],Table1[[#This Row],[Net Amount]]) -> -5049742.3
A14: 45373 | B14: ="TX"&TEXT(ROW()-1,"0000") -> TX0013 | C14: ADRO | D14: Dividend | E14: 59 | F14: {=_xlfn.IFS(Table1[[#This Row],[Action]]="Buy",Table1[[#This Row],[Lot ]],Table1[[#This Row],[Action]]="Sell",-Table1[[#This Row],[Lot ]],Table1[[#This Row],[Action]]="Dividend",0,TRUE,"")} -> 0 | H14: {=IF(OR(Table1[[#This Row],[Stock Tickers]]="",Table1[[#This Row],[Action]]="Dividend"), "",IF(Table1[[#This Row],[Action]]="Buy",(SUMIFS($L$2:L14, $C$2:C14,Table1[[#This Row],[Stock Tickers]], $D$2:D14, "Buy") + Table1[[#This Row],[Amount]]) / ((SUMIFS($E$2:E14, $C$2:C14,Table1[[#This Row],[Stock Tickers]], $D$2:D14, "Buy") + Table1[[#This Row],[Lot ]])*100),LOOKUP(2, 1/($C$2:C14=Table1[[#This Row],[Stock Tickers]]), $G$2:G14)))} | I14: 315 | J14: =(Table1[[#This Row],[Lot ]]*100)*IF(Table1[[#This Row],[Action]]="Dividend",Table1[[#This Row],[Dividend per Share]],Table1[[#This Row],[Price]]) -> 1858500 | L14: =SUM(Table1[[#This Row],[Amount]]:Table1[[#This Row],[Total Fee]]) -> 1858500 | M14: =IF(OR(Table1[[#This Row],[Action]]="Buy",Table1[[#This Row],[Action]]="Withdraw"),-Table1[[#This Row],[Net Amount]],Table1[[#This Row],[Net Amount]]) -> 1858500
A15: 45378 | B15: ="TX"&TEXT(ROW()-1,"0000") -> TX0014 | D15: Deposit | F15: {=_xlfn.IFS(Table1[[#This Row],[Action]]="Buy",Table1[[#This Row],[Lot ]],Table1[[#This Row],[Action]]="Sell",-Table1[[#This Row],[Lot ]],Table1[[#This Row],[Action]]="Dividend",0,TRUE,"")} | H15: {=IF(OR(Table1[[#This Row],[Stock Tickers]]="",Table1[[#This Row],[Action]]="Dividend"), "",IF(Table1[[#This Row],[Action]]="Buy",(SUMIFS($L$2:L15, $C$2:C15,Table1[[#This Row],[Stock Tickers]], $D$2:D15, "Buy") + Table1[[#This Row],[Amount]]) / ((SUMIFS($E$2:E15, $C$2:C15,Table1[[#This Row],[Stock Tickers]], $D$2:D15, "Buy") + Table1[[#This Row],[Lot ]])*100),LOOKUP(2, 1/($C$2:C15=Table1[[#This Row],[Stock Tickers]]), $G$2:G15)))} | J15: 45000000 | L15: =SUM(Table1[[#This Row],[Amount]]:Table1[[#This Row],[Total Fee]]) -> 45000000 | M15: =IF(OR(Table1[[#This Row],[Action]]="Buy",Table1[[#This Row],[Action]]="Withdraw"),-Table1[[#This Row],[Net Amount]],Table1[[#This Row],[Net Amount]]) -> 45000000
A16: 45386 | B16: ="TX"&TEXT(ROW()-1,"0000") -> TX0015 | C16: ICBP | D16: Buy | E16: 5 | F16: {=_xlfn.IFS(Table1[[#This Row],[Action]]="Buy",Table1[[#This Row],[Lot ]],Table1[[#This Row],[Action]]="Sell",-Table1[[#This Row],[Lot ]],Table1[[#This Row],[Action]]="Dividend",0,TRUE,"")} -> 5 | G16: 1150 | H16: {=IF(OR(Table1[[#This Row],[Stock Tickers]]="",Table1[[#This Row],[Action]]="Dividend"), "",IF(Table1[[#This Row],[Action]]="Buy",(SUMIFS($L$2:L16, $C$2:C16,Table1[[#This Row],[Stock Tickers]], $D$2:D16, "Buy") + Table1[[#This Row],[Amount]]) / ((SUMIFS($E$2:E16, $C$2:C16,Table1[[#This Row],[Stock Tickers]], $D$2:D16, "Buy") + Table1[[#This Row],[Lot ]])*100),LOOKUP(2, 1/($C$2:C16=Table1[[#This Row],[Stock Tickers]]), $G$2:G16)))} -> 1151.1115 | J16: =(Table1[[#This Row],[Lot ]]*100)*IF(Table1[[#This Row],[Action]]="Dividend",Table1[[#This Row],[Dividend per Share]],Table1[[#This Row],[Price]]) -> 575000 | K16: =(exchange_fee+broker_fee)*J16 -> 1111.475 | L16: =SUM(Table1[[#This Row],[Amount]]:Table1[[#This Row],[Total Fee]]) -> 576111.47 | M16: =IF(OR(Table1[[#This Row],[Action]]="Buy",Table1[[#This Row],[Action]]="Withdraw"),-Table1[[#This Row],[Net Amount]],Table1[[#This Row],[Net Amount]]) -> -576111.47
A17: 45392 | B17: ="TX"&TEXT(ROW()-1,"0000") -> TX0016 | C17: TLKM | D17: Buy | E17: 11 | F17: {=_xlfn.IFS(Table1[[#This Row],[Action]]="Buy",Table1[[#This Row],[Lot ]],Table1[[#This Row],[Action]]="Sell",-Table1[[#This Row],[Lot ]],Table1[[#This Row],[Action]]="Dividend",0,TRUE,"")} -> 11 | G17: 3840 | H17: {=IF(OR(Table1[[#This Row],[Stock Tickers]]="",Table1[[#This Row],[Action]]="Dividend"), "",IF(Table1[[#This Row],[Action]]="Buy",(SUMIFS($L$2:L17, $C$2:C17,Table1[[#This Row],[Stock Tickers]], $D$2:D17, "Buy") + Table1[[#This Row],[Amount]]) / ((SUMIFS($E$2:E17, $C$2:C17,Table1[[#This Row],[Stock Tickers]], $D$2:D17, "Buy") + Table1[[#This Row],[Lot ]])*100),LOOKUP(2, 1/($C$2:C17=Table1[[#This Row],[Stock Tickers]]), $G$2:G17)))} -> 3326.7073 | J17: =(Table1[[#This Row],[Lot ]]*100)*IF(Table1[[#This Row],[Action]]="Dividend",Table1[[#This Row],[Dividend per Share]],Table1[[#This Row],[Price]]) -> 4224000 | K17: =(exchange_fee+broker_fee)*J17 -> 8164.992 | L17: =SUM(Table1[[#This Row],[Amount]]:Table1[[#This Row],[Total Fee]]) -> 4232165 | M17: =IF(OR(Table1[[#This Row],[Action]]="Buy",Table1[[#This Row],[Action]]="Withdraw"),-Table1[[#This Row],[Net Amount]],Table1[[#This Row],[Net Amount]]) -> -4232165
A18: 45398 | B18: ="TX"&TEXT(ROW()-1,"0000") -> TX0017 | C18: BBRI | D18: Sell | E18: 4 | F18: {=_xlfn.IFS(Table1[[#This Row],[Action]]="Buy",Table1[[#This Row],[Lot ]],Table1[[#This Row],[Action]]="Sell",-Table1[[#This Row],[Lot ]],Table1[[#This Row],[Action]]="Dividend",0,TRUE,"")} -> -4 | G18: 6320 | H18: {=IF(OR(Table1[[#This Row],[Stock Tickers]]="",Table1[[#This Row],[Action]]="Dividend"), "",IF(Table1[[#This Row],[Action]]="Buy",(SUMIFS($L$2:L18, $C$2:C18,Table1[[#This Row],[Stock Tickers]], $D$2:D18, "Buy") + Table1[[#This Row],[Amount]]) / ((SUMIFS($E$2:E18, $C$2:C18,Table1[[#This Row],[Stock Tickers]], $D$2:D18, "Buy") + Table1[[#This Row],[Lot ]])*100),LOOKUP(2, 1/($C$2:C18=Table1[[#This Row],[Stock Tickers]]), $G$2:G18)))} -> 6320 | J18: =(Table1[[#This Row],[Lot ]]*100)*IF(Table1[[#This Row],[Action]]="Dividend",Table1[[#This Row],[Dividend per Share]],Table1[[#This Row],[Price]]) -> 2528000 | K18: =(exchange_fee+broker_fee)*J18 -> 4886.624 | L18: =SUM(Table1[[#This Row],[Amount]]:Table1[[#This Row],[Total Fee]]) -> 2532886.6 | M18: =IF(OR(Table1[[#This Row],[Action]]="Buy",Table1[[#This Row],[Action]]="Withdraw"),-Table1[[#This Row],[Net Amount]],Table1[[#This Row],[Net Amount]]) -> 2532886.6
A19: 45405 | B19: ="TX"&TEXT(ROW()-1,"0000") -> TX0018 | C19: BBCA | D19: Dividend | E19: 14 | F19: {=_xlfn.IFS(Table1[[#This Row],[Action]]="Buy",Table1[[#This Row],[Lot ]],Table1[[#This Row],[Action]]="Sell",-Table1[[#This Row],[Lot ]],Table1[[#This Row],[Action]]="Dividend",0,TRUE,"")} -> 0 | H19: {=IF(OR(Table1[[#This Row],[Stock Tickers]]="",Table1[[#This Row],[Action]]="Dividend"), "",IF(Table1[[#This Row],[Action]]="Buy",(SUMIFS($L$2:L19, $C$2:C19,Table1[[#This Row],[Stock Tickers]], $D$2:D19, "Buy") + Table1[[#This Row],[Amount]]) / ((SUMIFS($E$2:E19, $C$2:C19,Table1[[#This Row],[Stock Tickers]], $D$2:D19, "Buy") + Table1[[#This Row],[Lot ]])*100),LOOKUP(2, 1/($C$2:C19=Table1[[#This Row],[Stock Tickers]]), $G$2:G19)))} | I19: 50 | J19: =(Table1[[#This Row],[Lot ]]*100)*IF(Table1[[#This Row],[Action]]="Dividend",Table1[[#This Row],[Dividend per Share]],Table1[[#This Row],[Price]]) -> 70000 | L19: =SUM(Table1[[#This Row],[Amount]]:Table1[[#This Row],[Total Fee]]) -> 70000 | M19: =IF(OR(Table1[[#This Row],[Action]]="Buy",Table1[[#This Row],[Action]]="Withdraw"),-Table1[[#This Row],[Net Amount]],Table1[[#This Row],[Net Amount]]) -> 70000
A20: 45412 | B20: ="TX"&TEXT(ROW()-1,"0000") -> TX0019 | C20: ASII | D20: Buy | E20: 24 | F20: {=_xlfn.IFS(Table1[[#This Row],[Action]]="Buy",Table1[[#This Row],[Lot ]],Table1[[#This Row],[Action]]="Sell",-Table1[[#This Row],[Lot ]],Table1[[#This Row],[Action]]="Dividend",0,TRUE,"")} -> 24 | G20: 4410 | H20: {=IF(OR(Table1[[#This Row],[Stock Tickers]]="",Table1[[#This Row],[Action]]="Dividend"), "",IF(Table1[[#This Row],[Action]]="Buy",(SUMIFS($L$2:L20, $C$2:C20,Table1[[#This Row],[Stock Tickers]], $D$2:D20, "Buy") + Table1[[#This Row],[Amount]]) / ((SUMIFS($E$2:E20, $C$2:C20,Table1[[#This Row],[Stock Tickers]], $D$2:D20, "Buy") + Table1[[#This Row],[Lot ]])*100),LOOKUP(2, 1/($C$2:C20=Table1[[#This Row],[Stock Tickers]]), $G$2:G20)))} -> 4692.5007 | J20: =(Table1[[#This Row],[Lot ]]*100)*IF(Table1[[#This Row],[Action]]="Dividend",Table1[[#This Row],[Dividend per Share]],Table1[[#This Row],[Price]]) -> 10584000 | K20: =(exchange_fee+broker_fee)*J20 -> 20458.872 | L20: =SUM(Table1[[#This Row],[Amount]]:Table1[[#This Row],[Total Fee]]) -> 10604459 | M20: =IF(OR(Table1[[#This Row],[Action]]="Buy",Table1[[#This Row],[Action]]="Withdraw"),-Table1[[#This Row],[Net Amount]],Table1[[#This Row],[Net Amount]]) -> -10604459
A21: 45417 | B21: ="TX"&TEXT(ROW()-1,"0000") -> TX0020 | C21: BBRI | D21: Sell | E21: 10 | F21: {=_xlfn.IFS(Table1[[#This Row],[Action]]="Buy",Table1[[#This Row],[Lot ]],Table1[[#This Row],[Action]]="Sell",-Table1[[#This Row],[Lot ]],Table1[[#This Row],[Action]]="Dividend",0,TRUE,"")} -> -10 | G21: 6570 | H21: {=IF(OR(Table1[[#This Row],[Stock Tickers]]="",Table1[[#This Row],[Action]]="Dividend"), "",IF(Table1[[#This Row],[Action]]="Buy",(SUMIFS($L$2:L21, $C$2:C21,Table1[[#This Row],[Stock Tickers]], $D$2:D21, "Buy") + Table1[[#This Row],[Amount]]) / ((SUMIFS($E$2:E21, $C$2:C21,Table1[[#This Row],[Stock Tickers]], $D$2:D21, "Buy") + Table1[[#This Row],[Lot ]])*100),LOOKUP(2, 1/($C$2:C21=Table1[[#This Row],[Stock Tickers]]), $G$2:G21)))} -> 6570 | J21: =(Table1[[#This Row],[Lot ]]*100)*IF(Table1[[#This Row],[Action]]="Dividend",Table1[[#This Row],[Dividend per Share]],Table1[[#This Row],[Price]]) -> 6570000 | K21: =(exchange_fee+broker_fee)*J21 -> 12699.81 | L21: =SUM(Table1[[#This Row],[Amount]]:Table1[[#This Row],[Total Fee]]) -> 6582699.8 | M21: =IF(OR(Table1[[#This Row],[Action]]="Buy",Table1[[#This Row],[Action]]="Withdraw"),-Table1[[#This Row],[Net Amount]],Table1[[#This Row],[Net Amount]]) -> 6582699.8
A22: 45418 | B22: ="TX"&TEXT(ROW()-1,"0000") -> TX0021 | C22: GOTO | D22: Buy | E22: 100 | F22: {=_xlfn.IFS(Table1[[#This Row],[Action]]="Buy",Table1[[#This Row],[Lot ]],Table1[[#This Row],[Action]]="Sell",-Table1[[#This Row],[Lot ]],Table1[[#This Row],[Action]]="Dividend",0,TRUE,"")} -> 100 | G22: 128 | H22: {=IF(OR(Table1[[#This Row],[Stock Tickers]]="",Table1[[#This Row],[Action]]="Dividend"), "",IF(Table1[[#This Row],[Action]]="Buy",(SUMIFS($L$2:L22, $C$2:C22,Table1[[#This Row],[Stock Tickers]], $D$2:D22, "Buy") + Table1[[#This Row],[Amount]]) / ((SUMIFS($E$2:E22, $C$2:C22,Table1[[#This Row],[Stock Tickers]], $D$2:D22, "Buy") + Table1[[#This Row],[Lot ]])*100),LOOKUP(2, 1/($C$2:C22=Table1[[#This Row],[Stock Tickers]]), $G$2:G22)))} -> 128.12371 | J22: =(Table1[[#This Row],[Lot ]]*100)*IF(Table1[[#This Row],[Action]]="Dividend",Table1[[#This Row],[Dividend per Share]],Table1[[#This Row],[Price]]) -> 1280000 | K22: =(exchange_fee+broker_fee)*J22 -> 2474.24 | L22: =SUM(Table1[[#This Row],[Amount]]:Table1[[#This Row],[Total Fee]]) -> 1282474.2 | M22: =IF(OR(Table1[[#This Row],[Action]]="Buy",Table1[[#This Row],[Action]]="Withdraw"),-Table1[[#This Row],[Net Amount]],Table1[[#This Row],[Net Amount]]) -> -1282474.2
A23: 45429 | B23: ="TX"&TEXT(ROW()-1,"0000") -> TX0022 | C23: ADRO | D23: Buy | E23: 14 | F23: {=_xlfn.IFS(Table1[[#This Row],[Action]]="Buy",Table1[[#This Row],[Lot ]],Table1[[#This Row],[Action]]="Sell",-Table1[[#This Row],[Lot ]],Table1[[#This Row],[Action]]="Dividend",0,TRUE,"")} -> 14 | G23: 1870 | H23: {=IF(OR(Table1[[#This Row],[Stock Tickers]]="",Table1[[#This Row],[Action]]="Dividend"), "",IF(Table1[[#This Row],[Action]]="Buy",(SUMIFS($L$2:L23, $C$2:C23,Table1[[#This Row],[Stock Tickers]], $D$2:D23, "Buy") + Table1[[#This Row],[Amount]]) / ((SUMIFS($E$2:E23, $C$2:C23,Table1[[#This Row],[Stock Tickers]], $D$2:D23, "Buy") + Table1[[#This Row],[Lot ]])*100),LOOKUP(2, 1/($C$2:C23=Table1[[#This Row],[Stock Tickers]]), $G$2:G23)))} -> 2487.7823 | J23: =(Table1[[#This Row],[Lot ]]*100)*IF(Table1[[#This Row],[Action]]="Dividend",Table1[[#This Row],[Dividend per Share]],Table1[[#This Row],[Price]]) -> 2618000 | K23: =(exchange_fee+broker_fee)*J23 -> 5060.594 | L23: =SUM(Table1[[#This Row],[Amount]]:Table1[[#This Row],[Total Fee]]) -> 2623060.6 | M23: =IF(OR(Table1[[#This Row],[Action]]="Buy",Table1[[#This Row],[Action]]="Withdraw"),-Table1[[#This Row],[Net Amount]],Table1[[#This Row],[Net Amount]]) -> -2623060.6
A24: 45436 | B24: ="TX"&TEXT(ROW()-1,"0000") -> TX0023 | C24: ASII | D24: Dividend | E24: 56 | F24: {=_xlfn.IFS(Table1[[#This Row],[Action]]="Buy",Table1[[#This Row],[Lot ]],Table1[[#This Row],[Action]]="Sell",-Table1[[#This Row],[Lot ]],Table1[[#This Row],[Action]]="Dividend",0,TRUE,"")} -> 0 | H24: {=IF(OR(Table1[[#This Row],[Stock Tickers]]="",Table1[[#This Row],[Action]]="Dividend"), "",IF(Table1[[#This Row],[Action]]="Buy",(SUMIFS($L$2:L24, $C$2:C24,Table1[[#This Row],[Stock Tickers]], $D$2:D24, "Buy") + Table1[[#This Row],[Amount]]) / ((SUMIFS($E$2:E24, $C$2:C24,Table1[[#This Row],[Stock Tickers]], $D$2:D24, "Buy") + Table1[[#This Row],[Lot ]])*100),LOOKUP(2, 1/($C$2:C24=Table1[[#This Row],[Stock Tickers]]), $G$2:G24)))} | I24: 519 | J24: =(Table1[[#This Row],[Lot ]]*100)*IF(Table1[[#This Row],[Action]]="Dividend",Table1[[#This Row],[Dividend per Share]],Table1[[#This Row],[Price]]) -> 2906400 | L24: =SUM(Table1[[#This Row],[Amount]]:Table1[[#This Row],[Total Fee]]) -> 2906400 | M24: =IF(OR(Table1[[#This Row],[Action]]="Buy",Table1[[#This Row],[Action]]="Withdraw"),-Table1[[#This Row],[Net Amount]],Table1[[#This Row],[Net Amount]]) -> 2906400
A25: 45442 | B25: ="TX"&TEXT(ROW()-1,"0000") -> TX0024 | C25: BBRI | D25: Buy | E25: 12 | F25: {=_xlfn.IFS(Table1[[#This Row],[Action]]="Buy",Table1[[#This Row],[Lot ]],Table1[[#This Row],[Action]]="Sell",-Table1[[#This Row],[Lot ]],Table1[[#This Row],[Action]]="Dividend",0,TRUE,"")} -> 12 | G25: 4440 | H25: {=IF(OR(Table1[[#This Row],[Stock Tickers]]="",Table1[[#This Row],[Action]]="Dividend"), "",IF(Table1[[#This Row],[Action]]="Buy",(SUMIFS($L$2:L25, $C$2:C25,Table1[[#This Row],[Stock Tickers]], $D$2:D25, "Buy") + Table1[[#This Row],[Amount]]) / ((SUMIFS($E$2:E25, $C$2:C25,Table1[[#This Row],[Stock Tickers]], $D$2:D25, "Buy") + Table1[[#This Row],[Lot ]])*100),LOOKUP(2, 1/($C$2:C25=Table1[[#This Row],[Stock Tickers]]), $G$2:G25)))} -> 3928.8885 | J25: =(Table1[[#This Row],[Lot ]]*100)*IF(Table1[[#This Row],[Action]]="Dividend",Table1[[#This Row],[Dividend per Share]],Table1[[#This Row],[Price]]) -> 5328000 | K25: =(exchange_fee+broker_fee)*J25 -> 10299.024 | L25: =SUM(Table1[[#This Row],[Amount]]:Table1[[#This Row],[Total Fee]]) -> 5338299 | M25: =IF(OR(Table1[[#This Row],[Action]]="Buy",Table1[[#This Row],[Action]]="Withdraw"),-Table1[[#This Row],[Net Amount]],Table1[[#This Row],[Net Amount]]) -> -5338299
A26: 45449 | B26: ="TX"&TEXT(ROW()-1,"0000") -> TX0025 | C26: ITMG | D26: Buy | E26: 5 | F26: {=_xlfn.IFS(Table1[[#This Row],[Action]]="Buy",Table1[[#This Row],[Lot ]],Table1[[#This Row],[Action]]="Sell",-Table1[[#This Row],[Lot ]],Table1[[#This Row],[Action]]="Dividend",0,TRUE,"")} -> 5 | G26: 31100 | H26: {=IF(OR(Table1[[#This Row],[Stock Tickers]]="",Table1[[#This Row],[Action]]="Dividend"), "",IF(Table1[[#This Row],[Action]]="Buy",(SUMIFS($L$2:L26, $C$2:C26,Table1[[#This Row],[Stock Tickers]], $D$2:D26, "Buy") + Table1[[#This Row],[Amount]]) / ((SUMIFS($E$2:E26, $C$2:C26,Table1[[#This Row],[Stock Tickers]], $D$2:D26, "Buy") + Table1[[#This Row],[Lot ]])*100),LOOKUP(2, 1/($C$2:C26=Table1[[#This Row],[Stock Tickers]]), $G$2:G26)))} -> 30594.024 | J26: =(Table1[[#This Row],[Lot ]]*100)*IF(Table1[[#This Row],[Action]]="Dividend",Table1[[#This Row],[Dividend per Share]],Table1[[#This Row],[Price]]) -> 15550000 | K26: =(exchange_fee+broker_fee)*J26 -> 30058.15 | L26: =SUM(Table1[[#This Row],[Amount]]:Table1[[#This Row],[Total Fee]]) -> 15580058 | M26: =IF(OR(Table1[[#This Row],[Action]]="Buy",Table1[[#This Row],[Action]]="Withdraw"),-Table1[[#This Row],[Net Amount]],Table1[[#This Row],[Net Amount]]) -> -15580058
A27: 45455 | B27: ="TX"&TEXT(ROW()-1,"0000") -> TX0026 | C27: ICBP | D27: Buy | E27: 7 | F27: {=_xlfn.IFS(Table1[[#This Row],[Action]]="Buy",Table1[[#This Row],[Lot ]],Table1[[#This Row],[Action]]="Sell",-Table1[[#This Row],[Lot ]],Table1[[#This Row],[Action]]="Dividend",0,TRUE,"")} -> 7 | G27: 1060 | H27: {=IF(OR(Table1[[#This Row],[Stock Tickers]]="",Table1[[#This Row],[Action]]="Dividend"), "",IF(Table1[[#This Row],[Action]]="Buy",(SUMIFS($L$2:L27, $C$2:C27,Table1[[#This Row],[Stock Tickers]], $D$2:D27, "Buy") + Table1[[#This Row],[Amount]]) / ((SUMIFS($E$2:E27, $C$2:C27,Table1[[#This Row],[Stock Tickers]], $D$2:D27, "Buy") + Table1[[#This Row],[Lot ]])*100),LOOKUP(2, 1/($C$2:C27=Table1[[#This Row],[Stock Tickers]]), $G$2:G27)))} -> 1085.0241 | J27: =(Table1[[#This Row],[Lot ]]*100)*IF(Table1[[#This Row],[Action]]="Dividend",Table1[[#This Row],[Dividend per Share]],Table1[[#This Row],[Price]]) -> 742000 | K27: =(exchange_fee+broker_fee)*J27 -> 1434.286 | L27: =SUM(Table1[[#This Row],[Amount]]:Table1[[#This Row],[Total Fee]]) -> 743434.29 | M27: =IF(OR(Table1[[#This Row],[Action]]="Buy",Table1[[#This Row],[Action]]="Withdraw"),-Table1[[#This Row],[Net Amount]],Table1[[#This Row],[Net Amount]]) -> -743434.29
A28: 45461 | B28: ="TX"&TEXT(ROW()-1,"0000") -> TX0027 | C28: BBCA | D28: Buy | E28: 6 | F28: {=_xlfn.IFS(Table1[[#This Row],[Action]]="Buy",Table1[[#This Row],[Lot ]],Table1[[#This Row],[Action]]="Sell",-Table1[[#This Row],[Lot ]],Table1[[#This Row],[Action]]="Dividend",0,TRUE,"")} -> 6 | G28: 6190 | H28: {=IF(OR(Table1[[#This Row],[Stock Tickers]]="",Table1[[#This Row],[Action]]="Dividend"), "",IF(Table1[[#This Row],[Action]]="Buy",(SUMIFS($L$2:L28, $C$2:C28,Table1[[#This Row],[Stock Tickers]], $D$2:D28, "Buy") + Table1[[#This Row],[Amount]]) / ((SUMIFS($E$2:E28, $C$2:C28,Table1[[#This Row],[Stock Tickers]], $D$2:D28, "Buy") + Table1[[#This Row],[Lot ]])*100),LOOKUP(2, 1/($C$2:C28=Table1[[#This Row],[Stock Tickers]]), $G$2:G28)))} -> 6841.2119 | J28: =(Table1[[#This Row],[Lot ]]*100)*IF(Table1[[#This Row],[Action]]="Dividend",Table1[[#This Row],[Dividend per Share]],Table1[[#This Row],[Price]]) -> 3714000 | K28: =(exchange_fee+broker_fee)*J28 -> 7179.162 | L28: =SUM(Table1[[#This Row],[Amount]]:Table1[[#This Row],[Total Fee]]) -> 3721179.2 | M28: =IF(OR(Table1[[#This Row],[Action]]="Buy",Table1[[#This Row],[Action]]="Withdraw"),-Table1[[#This Row],[Net Amount]],Table1[[#This Row],[Net Amount]]) -> -3721179.2
A29: 45470 | B29: ="TX"&TEXT(ROW()-1,"0000") -> TX0028 | D29: Deposit | F29: {=_xlfn.IFS(Table1[[#This Row],[Action]]="Buy",Table1[[#This Row],[Lot ]],Table1[[#This Row],[Action]]="Sell",-Table1[[#This Row],[Lot ]],Table1[[#This Row],[Action]]="Dividend",0,TRUE,"")} | H29: {=IF(OR(Table1[[#This Row],[Stock Tickers]]="",Table1[[#This Row],[Action]]="Dividend"), "",IF(Table1[[#This Row],[Action]]="Buy",(SUMIFS($L$2:L29, $C$2:C29,Table1[[#This Row],[Stock Tickers]], $D$2:D29, "Buy") + Table1[[#This Row],[Amount]]) / ((SUMIFS($E$2:E29, $C$2:C29,Table1[[#This Row],[Stock Tickers]], $D$2:D29, "Buy") + Table1[[#This Row],[Lot ]])*100),LOOKUP(2, 1/($C$2:C29=Table1[[#This Row],[Stock Tickers]]), $G$2:G29)))} | J29: 60000000 | L29: =SUM(Table1[[#This Row],[Amount]]:Table1[[#This Row],[Total Fee]]) -> 60000000 | M29: =IF(OR(Table1[[#This Row],[Action]]="Buy",Table1[[#This Row],[Action]]="Withdraw"),-Table1[[#This Row],[Net Amount]],Table1[[#This Row],[Net Amount]]) -> 60000000
A30: 45473 | B30: ="TX"&TEXT(ROW()-1,"0000") -> TX0029 | C30: ITMG | D30: Dividend | E30: 15 | F30: {=_xlfn.IFS(Table1[[#This Row],[Action]]="Buy",Table1[[#This Row],[Lot ]],Table1[[#This Row],[Action]]="Sell",-Table1[[#This Row],[Lot ]],Table1[[#This Row],[Action]]="Dividend",0,TRUE,"")} -> 0 | H30: {=IF(OR(Table1[[#This Row],[Stock Tickers]]="",Table1[[#This Row],[Action]]="Dividend"), "",IF(Table1[[#This Row],[Action]]="Buy",(SUMIFS($L$2:L30, $C$2:C30,Table1[[#This Row],[Stock Tickers]], $D$2:D30, "Buy") + Table1[[#This Row],[Amount]]) / ((SUMIFS($E$2:E30, $C$2:C30,Table1[[#This Row],[Stock Tickers]], $D$2:D30, "Buy") + Table1[[#This Row],[Lot ]])*100),LOOKUP(2, 1/($C$2:C30=Table1[[#This Row],[Stock Tickers]]), $G$2:G30)))} | I30: 2975 | J30: =(Table1[[#This Row],[Lot ]]*100)*IF(Table1[[#This Row],[Action]]="Dividend",Table1[[#This Row],[Dividend per Share]],Table1[[#This Row],[Price]]) -> 4462500 | L30: =SUM(Table1[[#This Row],[Amount]]:Table1[[#This Row],[Total Fee]]) -> 4462500 | M30: =IF(OR(Table1[[#This Row],[Action]]="Buy",Table1[[#This Row],[Action]]="Withdraw"),-Table1[[#This Row],[Net Amount]],Table1[[#This Row],[Net Amount]]) -> 4462500
A31: 45480 | B31: ="TX"&TEXT(ROW()-1,"0000") -> TX0030 | C31: ASII | D31: Buy | E31: 12 | F31: {=_xlfn.IFS(Table1[[#This Row],[Action]]="Buy",Table1[[#This Row],[Lot ]],Table1[[#This Row],[Action]]="Sell",-Table1[[#This Row],[Lot ]],Table1[[#This Row],[Action]]="Dividend",0,TRUE,"")} -> 12 | G31: 4950 | H31: {=IF(OR(Table1[[#This Row],[Stock Tickers]]="",Table1[[#This Row],[Action]]="Dividend"), "",IF(Table1[[#This Row],[Action]]="Buy",(SUMIFS($L$2:L31, $C$2:C31,Table1[[#This Row],[Stock Tickers]], $D$2:D31, "Buy") + Table1[[#This Row],[Amount]]) / ((SUMIFS($E$2:E31, $C$2:C31,Table1[[#This Row],[Stock Tickers]], $D$2:D31, "Buy") + Table1[[#This Row],[Lot ]])*100),LOOKUP(2, 1/($C$2:C31=Table1[[#This Row],[Stock Tickers]]), $G$2:G31)))} -> 4855.9359 | J31: =(Table1[[#This Row],[Lot ]]*100)*IF(Table1[[#This Row],[Action]]="Dividend",Table1[[#This Row],[Dividend per Share]],Table1[[#This Row],[Price]]) -> 5940000 | K31: =(exchange_fee+broker_fee)*J31 -> 11482.02 | L31: =SUM(Table1[[#This Row],[Amount]]:Table1[[#This Row],[Total Fee]]) -> 5951482 | M31: =IF(OR(Table1[[#This Row],[Action]]="Buy",Table1[[#This Row],[Action]]="Withdraw"),-Table1[[#This Row],[Net Amount]],Table1[[#This Row],[Net Amount]]) -> -5951482
A32: 45481 | B32: ="TX"&TEXT(ROW()-1,"0000") -> TX0031 | C32: ITMG | D32: Buy | E32: 14 | F32: {=_xlfn.IFS(Table1[[#This Row],[Action]]="Buy",Table1[[#This Row],[Lot ]],Table1[[#This Row],[Action]]="Sell",-Table1[[#This Row],[Lot ]],Table1[[#This Row],[Action]]="Dividend",0,TRUE,"")} -> 14 | G32: 27300 | H32: {=IF(OR(Table1[[#This Row],[Stock Tickers]]="",Table1[[#This Row],[Action]]="Dividend"), "",IF(Table1[[#This Row],[Action]]="Buy",(SUMIFS($L$2:L32, $C$2:C32,Table1[[#This Row],[Stock Tickers]], $D$2:D32, "Buy") + Table1[[#This Row],[Amount]]) / ((SUMIFS($E$2:E32, $C$2:C32,Table1[[#This Row],[Stock Tickers]], $D$2:D32, "Buy") + Table1[[#This Row],[Lot ]])*100),LOOKUP(2, 1/($C$2:C32=Table1[[#This Row],[Stock Tickers]]), $G$2:G32)))} -> 28407.425 | J32: =(Table1[[#This Row],[Lot ]]*100)*IF(Table1[[#This Row],[Action]]="Dividend",Table1[[#This Row],[Dividend per Share]],Table1[[#This Row],[Price]]) -> 38220000 | K32: =(exchange_fee+broker_fee)*J32 -> 73879.26 | L32: =SUM(Table1[[#This Row],[Amount]]:Table1[[#This Row],[Total Fee]]) -> 38293879 | M32: =IF(OR(Table1[[#This Row],[Action]]="Buy",Table1[[#This Row],[Action]]="Withdraw"),-Table1[[#This Row],[Net Amount]],Table1[[#This Row],[Net Amount]]) -> -38293879
A33: 45488 | B33: ="TX"&TEXT(ROW()-1,"0000") -> TX0032 | C33: BBRI | D33: Buy | E33: 9 | F33: {=_xlfn.IFS(Table1[[#This Row],[Action]]="Buy",Table1[[#This Row],[Lot ]],Table1[[#This Row],[Action]]="Sell",-Table1[[#This Row],[Lot ]],Table1[[#This Row],[Action]]="Dividend",0,TRUE,"")} -> 9 | G33: 4170 | H33: {=IF(OR(Table1[[#This Row],[Stock Tickers]]="",Table1[[#This Row],[Action]]="Dividend"), "",IF(Table1[[#This Row],[Action]]="Buy",(SUMIFS($L$2:L33, $C$2:C33,Table1[[#This Row],[Stock Tickers]], $D$2:D33, "Buy") + Table1[[#This Row],[Amount]]) / ((SUMIFS($E$2:E33, $C$2:C33,Table1[[#This Row],[Stock Tickers]], $D$2:D33, "Buy") + Table1[[#This Row],[Lot ]])*100),LOOKUP(2, 1/($C$2:C33=Table1[[#This Row],[Stock Tickers]]), $G$2:G33)))} -> 3902.4149 | J33: =(Table1[[#This Row],[Lot ]]*100)*IF(Table1[[#This Row],[Action]]="Dividend",Table1[[#This Row],[Dividend per Share]],Table1[[#This Row],[Price]]) -> 3753000 | K33: =(exchange_fee+broker_fee)*J33 -> 7254.549 | L33: =SUM(Table1[[#This Row],[Amount]]:Table1[[#This Row],[Total Fee]]) -> 3760254.5 | M33: =IF(OR(Table1[[#This Row],[Action]]="Buy",Table1[[#This Row],[Action]]="Withdraw"),-Table1[[#This Row],[Net Amount]],Table1[[#This Row],[Net Amount]]) -> -3760254.5
A34: 45495 | B34: ="TX"&TEXT(ROW()-1,"0000") -> TX0033 | D34: Deposit | F34: {=_xlfn.IFS(Table1[[#This Row],[Action]]="Buy",Table1[[#This Row],[Lot ]],Table1[[#This Row],[Action]]="Sell",-Table1[[#This Row],[Lot ]],Table1[[#This Row],[Action]]="Dividend",0,TRUE,"")} | H34: {=IF(OR(Table1[[#This Row],[Stock Tickers]]="",Table1[[#This Row],[Action]]="Dividend"), "",IF(Table1[[#This Row],[Action]]="Buy",(SUMIFS($L$2:L34, $C$2:C34,Table1[[#This Row],[Stock Tickers]], $D$2:D34, "Buy") + Table1[[#This Row],[Amount]]) / ((SUMIFS($E$2:E34, $C$2:C34,Table1[[#This Row],[Stock Tickers]], $D$2:D34, "Buy") + Table1[[#This Row],[Lot ]])*100),LOOKUP(2, 1/($C$2:C34=Table1[[#This Row],[Stock Tickers]]), $G$2:G34)))} | J34: 100000000 | L34: =SUM(Table1[[#This Row],[Amount]]:Table1[[#This Row],[Total Fee]]) -> 100000000 | M34: =IF(OR(Table1[[#This Row],[Action]]="Buy",Table1[[#This Row],[Action]]="Withdraw"),-Table1[[#This Row],[Net Amount]],Table1[[#This Row],[Net Amount]]) -> 100000000
A35: 45504 | B35: ="TX"&TEXT(ROW()-1,"0000") -> TX0034 | C35: TLKM | D35: Buy | E35: 15 | F35: {=_xlfn.IFS(Table1[[#This Row],[Action]]="Buy",Table1[[#This Row],[Lot ]],Table1[[#This Row],[Action]]="Sell",-Table1[[#This Row],[Lot ]],Table1[[#This Row],[Action]]="Dividend",0,TRUE,"")} -> 15 | G35: 3220 | H35: {=IF(OR(Table1[[#This Row],[Stock Tickers]]="",Table1[[#This Row],[Action]]="Dividend"), "",IF(Table1[[#This Row],[Action]]="Buy",(SUMIFS($L$2:L35, $C$2:C35,Table1[[#This Row],[Stock Tickers]], $D$2:D35, "Buy") + Table1[[#This Row],[Amount]]) / ((SUMIFS($E$2:E35, $C$2:C35,Table1[[#This Row],[Stock Tickers]], $D$2:D35, "Buy") + Table1[[#This Row],[Lot ]])*100),LOOKUP(2, 1/($C$2:C35=Table1[[#This Row],[Stock Tickers]]), $G$2:G35)))} -> 3221.2365 | J35: =(Table1[[#This Row],[Lot ]]*100)*IF(Table1[[#This Row],[Action]]="Dividend",Table1[[#This Row],[Dividend per Share]],Table1[[#This Row],[Price]]) -> 4830000 | K35: =(exchange_fee+broker_fee)*J35 -> 9336.39 | L35: =SUM(Table1[[#This Row],[Amount]]:Table1[[#This Row],[Total Fee]]) -> 4839336.4 | M35: =IF(OR(Table1[[#This Row],[Action]]="Buy",Table1[[#This Row],[Action]]="Withdraw"),-Table1[[#This Row],[Net Amount]],Table1[[#This Row],[Net Amount]]) -> -4839336.4
A36: 45512 | B36: ="TX"&TEXT(ROW()-1,"0000") -> TX0035 | C36: BBCA | D36: Sell | E36: 5 | F36: {=_xlfn.IFS(Table1[[#This Row],[Action]]="Buy",Table1[[#This Row],[Lot ]],Table1[[#This Row],[Action]]="Sell",-Table1[[#This Row],[Lot ]],Table1[[#This Row],[Action]]="Dividend",0,TRUE,"")} -> -5 | G36: 9350 | H36: {=IF(OR(Table1[[#This Row],[Stock Tickers]]="",Table1[[#This Row],[Action]]="Dividend"), "",IF(Table1[[#This Row],[Action]]="Buy",(SUMIFS($L$2:L36, $C$2:C36,Table1[[#This Row],[Stock Tickers]], $D$2:D36, "Buy") + Table1[[#This Row],[Amount]]) / ((SUMIFS($E$2:E36, $C$2:C36,Table1[[#This Row],[Stock Tickers]], $D$2:D36, "Buy") + Table1[[#This Row],[Lot ]])*100),LOOKUP(2, 1/($C$2:C36=Table1[[#This Row],[Stock Tickers]]), $G$2:G36)))} -> 9350 | J36: =(Table1[[#This Row],[Lot ]]*100)*IF(Table1[[#This Row],[Action]]="Dividend",Table1[[#This Row],[Dividend per Share]],Table1[[#This Row],[Price]]) -> 4675000 | K36: =(exchange_fee+broker_fee)*J36 -> 9036.775 | L36: =SUM(Table1[[#This Row],[Amount]]:Table1[[#This Row],[Total Fee]]) -> 4684036.8 | M36: =IF(OR(Table1[[#This Row],[Action]]="Buy",Table1[[#This Row],[Action]]="Withdraw"),-Table1[[#This Row],[Net Amount]],Table1[[#This Row],[Net Amount]]) -> 4684036.8
A37: 45512 | B37: ="TX"&TEXT(ROW()-1,"0000") -> TX0036 | C37: ADRO | D37: Buy | E37: 16 | F37: {=_xlfn.IFS(Table1[[#This Row],[Action]]="Buy",Table1[[#This Row],[Lot ]],Table1[[#This Row],[Action]]="Sell",-Table1[[#This Row],[Lot ]],Table1[[#This Row],[Action]]="Dividend",0,TRUE,"")} -> 16 | G37: 1990 | H37: {=IF(OR(Table1[[#This Row],[Stock Tickers]]="",Table1[[#This Row],[Action]]="Dividend"), "",IF(Table1[[#This Row],[Action]]="Buy",(SUMIFS($L$2:L37, $C$2:C37,Table1[[#This Row],[Stock Tickers]], $D$2:D37, "Buy") + Table1[[#This Row],[Amount]]) / ((SUMIFS($E$2:E37, $C$2:C37,Table1[[#This Row],[Stock Tickers]], $D$2:D37, "Buy") + Table1[[#This Row],[Lot ]])*100),LOOKUP(2, 1/($C$2:C37=Table1[[#This Row],[Stock Tickers]]), $G$2:G37)))} -> 2419.0343 | J37: =(Table1[[#This Row],[Lot ]]*100)*IF(Table1[[#This Row],[Action]]="Dividend",Table1[[#This Row],[Dividend per Share]],Table1[[#This Row],[Price]]) -> 3184000 | K37: =(exchange_fee+broker_fee)*J37 -> 6154.672 | L37: =SUM(Table1[[#This Row],[Amount]]:Table1[[#This Row],[Total Fee]]) -> 3190154.7 | M37: =IF(OR(Table1[[#This Row],[Action]]="Buy",Table1[[#This Row],[Action]]="Withdraw"),-Table1[[#This Row],[Net Amount]],Table1[[#This Row],[Net Amount]]) -> -3190154.7
A38: 45515 | B38: ="TX"&TEXT(ROW()-1,"0000") -> TX0037 | D38: Deposit | F38: {=_xlfn.IFS(Table1[[#This Row],[Action]]="Buy",Table1[[#This Row],[Lot ]],Table1[[#This Row],[Action]]="Sell",-Table1[[#This Row],[Lot ]],Table1[[#This Row],[Action]]="Dividend",0,TRUE,"")} | H38: {=IF(OR(Table1[[#This Row],[Stock Tickers]]="",Table1[[#This Row],[Action]]="Dividend"), "",IF(Table1[[#This Row],[Action]]="Buy",(SUMIFS($L$2:L38, $C$2:C38,Table1[[#This Row],[Stock Tickers]], $D$2:D38, "Buy") + Table1[[#This Row],[Amount]]) / ((SUMIFS($E$2:E38, $C$2:C38,Table1[[#This Row],[Stock Tickers]], $D$2:D38, "Buy") + Table1[[#This Row],[Lot ]])*100),LOOKUP(2, 1/($C$2:C38=Table1[[#This Row],[Stock Tickers]]), $G$2:G38)))} | J38: 45000000 | L38: =SUM(Table1[[#This Row],[Amount]]:Table1[[#This Row],[Total Fee]]) -> 45000000 | M38: =IF(OR(Table1[[#This Row],[Action]]="Buy",Table1[[#This Row],[Action]]="Withdraw"),-Table1[[#This Row],[Net Amount]],Table1[[#This Row],[Net Amount]]) -> 45000000
A39: 45523 | B39: ="TX"&TEXT(ROW()-1,"0000") -> TX0038 | C39: ICBP | D39: Dividend | E39: 12 | F39: {=_xlfn.IFS(Table1[[#This Row],[Action]]="Buy",Table1[[#This Row],[Lot ]],Table1[[#This Row],[Action]]="Sell",-Table1[[#This Row],[Lot ]],Table1[[#This Row],[Action]]="Dividend",0,TRUE,"")} -> 0 | H39: {=IF(OR(Table1[[#This Row],[Stock Tickers]]="",Table1[[#This Row],[Action]]="Dividend"), "",IF(Table1[[#This Row],[Action]]="Buy",(SUMIFS($L$2:L39, $C$2:C39,Table1[[#This Row],[Stock Tickers]], $D$2:D39, "Buy") + Table1[[#This Row],[Amount]]) / ((SUMIFS($E$2:E39, $C$2:C39,Table1[[#This Row],[Stock Tickers]], $D$2:D39, "Buy") + Table1[[#This Row],[Lot ]])*100),LOOKUP(2, 1/($C$2:C39=Table1[[#This Row],[Stock Tickers]]), $G$2:G39)))} | I39: 200 | J39: =(Table1[[#This Row],[Lot ]]*100)*IF(Table1[[#This Row],[Action]]="Dividend",Table1[[#This Row],[Dividend per Share]],Table1[[#This Row],[Price]]) -> 240000 | L39: =SUM(Table1[[#This Row],[Amount]]:Table1[[#This Row],[Total Fee]]) -> 240000 | M39: =IF(OR(Table1[[#This Row],[Action]]="Buy",Table1[[#This Row],[Action]]="Withdraw"),-Table1[[#This Row],[Net Amount]],Table1[[#This Row],[Net Amount]]) -> 240000
A40: 45525 | B40: ="TX"&TEXT(ROW()-1,"0000") -> TX0039 | C40: BBRI | D40: Buy | E40: 34 | F40: {=_xlfn.IFS(Table1[[#This Row],[Action]]="Buy",Table1[[#This Row],[Lot ]],Table1[[#This Row],[Action]]="Sell",-Table1[[#This Row],[Lot ]],Table1[[#This Row],[Action]]="Dividend",0,TRUE,"")} -> 34 | G40: 3810 | H40: {=IF(OR(Table1[[#This Row],[Stock Tickers]]="",Table1[[#This Row],[Action]]="Dividend"), "",IF(Table1[[#This Row],[Action]]="Buy",(SUMIFS($L$2:L40, $C$2:C40,Table1[[#This Row],[Stock Tickers]], $D$2:D40, "Buy") + Table1[[#This Row],[Amount]]) / ((SUMIFS($E$2:E40, $C$2:C40,Table1[[#This Row],[Stock Tickers]], $D$2:D40, "Buy") + Table1[[#This Row],[Lot ]])*100),LOOKUP(2, 1/($C$2:C40=Table1[[#This Row],[Stock Tickers]]), $G$2:G40)))} -> 3834.3336 | J40: =(Table1[[#This Row],[Lot ]]*100)*IF(Table1[[#This Row],[Action]]="Dividend",Table1[[#This Row],[Dividend per Share]],Table1[[#This Row],[Price]]) -> 12954000 | K40: =(exchange_fee+broker_fee)*J40 -> 25040.082 | L40: =SUM(Table1[[#This Row],[Amount]]:Table1[[#This Row],[Total Fee]]) -> 12979040 | M40: =IF(OR(Table1[[#This Row],[Action]]="Buy",Table1[[#This Row],[Action]]="Withdraw"),-Table1[[#This Row],[Net Amount]],Table1[[#This Row],[Net Amount]]) -> -12979040
...

Sheet Simulation
A1: Stock Ticker | B1: Growth Percentage | C1: 2027 | D1: 2028 | E1: 2029 | F1: 2030 | G1: 2031 | H1: 2032 | I1: 2033 | J1: 2034 | K1: 2035 | L1: 2036
A2: ='Database '!$A$11 -> ADRO | B2: ='Database '!B28 -> 0.06 | C2: =SUMIF('Database '!$A$11:$A$22,A2,'Database '!$G$11:$G$22)*(1+Table2[[#This Row],[Growth Percentage]])^(Table2[[#Headers],[2027]]-YEAR(TODAY())) -> 65010142 | D2: =SUMIF('Database '!$A$11:$A$22,A2,'Database '!$G$11:$G$22)*(1+Table2[[#This Row],[Growth Percentage]])^(Table2[[#Headers],[2028]]-YEAR(TODAY())) -> 68910751 | E2: =SUMIF('Database '!$A$11:$A$22,A2,'Database '!$G$11:$G$22)*(1+Table2[[#This Row],[Growth Percentage]])^(Table2[[#Headers],[2029]]-YEAR(TODAY())) -> 73045396 | F2: =SUMIF('Database '!$A$11:$A$22,A2,'Database '!$G$11:$G$22)*(1+Table2[[#This Row],[Growth Percentage]])^(Table2[[#Headers],[2030]]-YEAR(TODAY())) -> 77428119 | G2: =SUMIF('Database '!$A$11:$A$22,A2,'Database '!$G$11:$G$22)*(1+Table2[[#This Row],[Growth Percentage]])^(Table2[[#Headers],[2031]]-YEAR(TODAY())) -> 82073807 | H2: =SUMIF('Database '!$A$11:$A$22,A2,'Database '!$G$11:$G$22)*(1+Table2[[#This Row],[Growth Percentage]])^(Table2[[#Headers],[2032]]-YEAR(TODAY())) -> 86998235 | I2: =SUMIF('Database '!$A$11:$A$22,A2,'Database '!$G$11:$G$22)*(1+Table2[[#This Row],[Growth Percentage]])^(Table2[[#Headers],[2033]]-YEAR(TODAY())) -> 92218129 | J2: =SUMIF('Database '!$A$11:$A$22,A2,'Database '!$G$11:$G$22)*(1+Table2[[#This Row],[Growth Percentage]])^(Table2[[#Headers],[2034]]-YEAR(TODAY())) -> 97751217 | K2: =SUMIF('Database '!$A$11:$A$22,A2,'Database '!$G$11:$G$22)*(1+Table2[[#This Row],[Growth Percentage]])^(Table2[[#Headers],[2035]]-YEAR(TODAY())) -> 1.0361629e+08 | L2: =SUMIF('Database '!$A$11:$A$22,A2,'Database '!$G$11:$G$22)*(1+Table2[[#This Row],[Growth Percentage]])^(Table2[[#Headers],[2036]]-YEAR(TODAY())) -> 1.0983327e+08
A3: ='Database '!$A$11 -> ADRO | B3: ='Database '!C28 -> 0.07 | C3: =SUMIF('Database '!$A$11:$A$22,A3,'Database '!$G$11:$G$22)*(1+Table2[[#This Row],[Growth Percentage]])^(Table2[[#Headers],[2027]]-YEAR(TODAY())) -> 65623445 | D3: =SUMIF('Database '!$A$11:$A$22,A3,'Database '!$G$11:$G$22)*(1+Table2[[#This Row],[Growth Percentage]])^(Table2[[#Headers],[2028]]-YEAR(TODAY())) -> 70217087 | E3: =SUMIF('Database '!$A$11:$A$22,A3,'Database '!$G$11:$G$22)*(1+Table2[[#This Row],[Growth Percentage]])^(Table2[[#Headers],[2029]]-YEAR(TODAY())) -> 75132283 | F3: =SUMIF('Database '!$A$11:$A$22,A3,'Database '!$G$11:$G$22)*(1+Table2[[#This Row],[Growth Percentage]])^(Table2[[#Headers],[2030]]-YEAR(TODAY())) -> 80391542 | G3: =SUMIF('Database '!$A$11:$A$22,A3,'Database '!$G$11:$G$22)*(1+Table2[[#This Row],[Growth Percentage]])^(Table2[[#Headers],[2031]]-YEAR(TODAY())) -> 86018950 | H3: =SUMIF('Database '!$A$11:$A$22,A3,'Database '!$G$11:$G$22)*(1+Table2[[#This Row],[Growth Percentage]])^(Table2[[#Headers],[2032]]-YEAR(TODAY())) -> 92040277 | I3: =SUMIF('Database '!$A$11:$A$22,A3,'Database '!$G$11:$G$22)*(1+Table2[[#This Row],[Growth Percentage]])^(Table2[[#Headers],[2033]]-YEAR(TODAY())) -> 98483096 | J3: =SUMIF('Database '!$A$11:$A$22,A3,'Database '!$G$11:$G$22)*(1+Table2[[#This Row],[Growth Percentage]])^(Table2[[#Headers],[2034]]-YEAR(TODAY())) -> 1.0537691e+08 | K3: =SUMIF('Database '!$A$11:$A$22,A3,'Database '!$G$11:$G$22)*(1+Table2[[#This Row],[Growth Percentage]])^(Table2[[#Headers],[2035]]-YEAR(TODAY())) -> 1.127533e+08 | L3: =SUMIF('Database '!$A$11:$A$22,A3,'Database '!$G$11:$G$22)*(1+Table2[[#This Row],[Growth Percentage]])^(Table2[[#Headers],[2036]]-YEAR(TODAY())) -> 1.2064603e+08
A4: ='Database '!$A$11 -> ADRO | B4: ='Database '!D28 -> 0.08 | C4: =SUMIF('Database '!$A$11:$A$22,A4,'Database '!$G$11:$G$22)*(1+Table2[[#This Row],[Growth Percentage]])^(Table2[[#Headers],[2027]]-YEAR(TODAY())) -> 66236749 | D4: =SUMIF('Database '!$A$11:$A$22,A4,'Database '!$G$11:$G$22)*(1+Table2[[#This Row],[Growth Percentage]])^(Table2[[#Headers],[2028]]-YEAR(TODAY())) -> 71535689 | E4: =SUMIF('Database '!$A$11:$A$22,A4,'Database '!$G$11:$G$22)*(1+Table2[[#This Row],[Growth Percentage]])^(Table2[[#Headers],[2029]]-YEAR(TODAY())) -> 77258544 | F4: =SUMIF('Database '!$A$11:$A$22,A4,'Database '!$G$11:$G$22)*(1+Table2[[#This Row],[Growth Percentage]])^(Table2[[#Headers],[2030]]-YEAR(TODAY())) -> 83439227 | G4: =SUMIF('Database '!$A$11:$A$22,A4,'Database '!$G$11:$G$22)*(1+Table2[[#This Row],[Growth Percentage]])^(Table2[[#Headers],[2031]]-YEAR(TODAY())) -> 90114365 | H4: =SUMIF('Database '!$A$11:$A$22,A4,'Database '!$G$11:$G$22)*(1+Table2[[#This Row],[Growth Percentage]])^(Table2[[#Headers],[2032]]-YEAR(TODAY())) -> 97323514 | I4: =SUMIF('Database '!$A$11:$A$22,A4,'Database '!$G$11:$G$22)*(1+Table2[[#This Row],[Growth Percentage]])^(Table2[[#Headers],[2033]]-YEAR(TODAY())) -> 1.051094e+08 | J4: =SUMIF('Database '!$A$11:$A$22,A4,'Database '!$G$11:$G$22)*(1+Table2[[#This Row],[Growth Percentage]])^(Table2[[#Headers],[2034]]-YEAR(TODAY())) -> 1.1351815e+08 | K4: =SUMIF('Database '!$A$11:$A$22,A4,'Database '!$G$11:$G$22)*(1+Table2[[#This Row],[Growth Percentage]])^(Table2[[#Headers],[2035]]-YEAR(TODAY())) -> 1.225996e+08 | L4: =SUMIF('Database '!$A$11:$A$22,A4,'Database '!$G$11:$G$22)*(1+Table2[[#This Row],[Growth Percentage]])^(Table2[[#Headers],[2036]]-YEAR(TODAY())) -> 1.3240757e+08
A5: ='Database '!$A$11 -> ADRO | B5: ='Database '!E28 -> 0.09 | C5: =SUMIF('Database '!$A$11:$A$22,A5,'Database '!$G$11:$G$22)*(1+Table2[[#This Row],[Growth Percentage]])^(Table2[[#Headers],[2027]]-YEAR(TODAY())) -> 66850052 | D5: =SUMIF('Database '!$A$11:$A$22,A5,'Database '!$G$11:$G$22)*(1+Table2[[#This Row],[Growth Percentage]])^(Table2[[#Headers],[2028]]-YEAR(TODAY())) -> 72866557 | E5: =SUMIF('Database '!$A$11:$A$22,A5,'Database '!$G$11:$G$22)*(1+Table2[[#This Row],[Growth Percentage]])^(Table2[[#Headers],[2029]]-YEAR(TODAY())) -> 79424547 | F5: =SUMIF('Database '!$A$11:$A$22,A5,'Database '!$G$11:$G$22)*(1+Table2[[#This Row],[Growth Percentage]])^(Table2[[#Headers],[2030]]-YEAR(TODAY())) -> 86572756 | G5: =SUMIF('Database '!$A$11:$A$22,A5,'Database '!$G$11:$G$22)*(1+Table2[[#This Row],[Growth Percentage]])^(Table2[[#Headers],[2031]]-YEAR(TODAY())) -> 94364304 | H5: =SUMIF('Database '!$A$11:$A$22,A5,'Database '!$G$11:$G$22)*(1+Table2[[#This Row],[Growth Percentage]])^(Table2[[#Headers],[2032]]-YEAR(TODAY())) -> 1.0285709e+08 | I5: =SUMIF('Database '!$A$11:$A$22,A5,'Database '!$G$11:$G$22)*(1+Table2[[#This Row],[Growth Percentage]])^(Table2[[#Headers],[2033]]-YEAR(TODAY())) -> 1.1211423e+08 | J5: =SUMIF('Database '!$A$11:$A$22,A5,'Database '!$G$11:$G$22)*(1+Table2[[#This Row],[Growth Percentage]])^(Table2[[#Headers],[2034]]-YEAR(TODAY())) -> 1.2220451e+08 | K5: =SUMIF('Database '!$A$11:$A$22,A5,'Database '!$G$11:$G$22)*(1+Table2[[#This Row],[Growth Percentage]])^(Table2[[#Headers],[2035]]-YEAR(TODAY())) -> 1.3320292e+08 | L5: =SUMIF('Database '!$A$11:$A$22,A5,'Database '!$G$11:$G$22)*(1+Table2[[#This Row],[Growth Percentage]])^(Table2[[#Headers],[2036]]-YEAR(TODAY())) -> 1.4519118e+08
A6: ='Database '!$A$11 -> ADRO | B6: ='Database '!F28 -> 0.095 | C6: =SUMIF('Database '!$A$11:$A$22,A6,'Database '!$G$11:$G$22)*(1+Table2[[#This Row],[Growth Percentage]])^(Table2[[#Headers],[2027]]-YEAR(TODAY())) -> 67156703 | D6: =SUMIF('Database '!$A$11:$A$22,A6,'Database '!$G$11:$G$22)*(1+Table2[[#This Row],[Growth Percentage]])^(Table2[[#Headers],[2028]]-YEAR(TODAY())) -> 73536590 | E6: =SUMIF('Database '!$A$11:$A$22,A6,'Database '!$G$11:$G$22)*(1+Table2[[#This Row],[Growth Percentage]])^(Table2[[#Headers],[2029]]-YEAR(TODAY())) -> 80522566 | F6: =SUMIF('Database '!$A$11:$A$22,A6,'Database '!$G$11:$G$22)*(1+Table2[[#This Row],[Growth Percentage]])^(Table2[[#Headers],[2030]]-YEAR(TODAY())) -> 88172210 | G6: =SUMIF('Database '!$A$11:$A$22,A6,'Database '!$G$11:$G$22)*(1+Table2[[#This Row],[Growth Percentage]])^(Table2[[#Headers],[2031]]-YEAR(TODAY())) -> 96548570 | H6: =SUMIF('Database '!$A$11:$A$22,A6,'Database '!$G$11:$G$22)*(1+Table2[[#This Row],[Growth Percentage]])^(Table2[[#Headers],[2032]]-YEAR(TODAY())) -> 1.0572068e+08 | I6: =SUMIF('Database '!$A$11:$A$22,A6,'Database '!$G$11:$G$22)*(1+Table2[[#This Row],[Growth Percentage]])^(Table2[[#Headers],[2033]]-YEAR(TODAY())) -> 1.1576415e+08 | J6: =SUMIF('Database '!$A$11:$A$22,A6,'Database '!$G$11:$G$22)*(1+Table2[[#This Row],[Growth Percentage]])^(Table2[[#Headers],[2034]]-YEAR(TODAY())) -> 1.2676174e+08 | K6: =SUMIF('Database '!$A$11:$A$22,A6,'Database '!$G$11:$G$22)*(1+Table2[[#This Row],[Growth Percentage]])^(Table2[[#Headers],[2035]]-YEAR(TODAY())) -> 1.3880411e+08 | L6: =SUMIF('Database '!$A$11:$A$22,A6,'Database '!$G$11:$G$22)*(1+Table2[[#This Row],[Growth Percentage]])^(Table2[[#Headers],[2036]]-YEAR(TODAY())) -> 1.519905e+08
A7: ='Database '!$A$11 -> ADRO | B7: ='Database '!G28 -> 0.1 | C7: =SUMIF('Database '!$A$11:$A$22,A7,'Database '!$G$11:$G$22)*(1+Table2[[#This Row],[Growth Percentage]])^(Table2[[#Headers],[2027]]-YEAR(TODAY())) -> 67463355 | D7: =SUMIF('Database '!$A$11:$A$22,A7,'Database '!$G$11:$G$22)*(1+Table2[[#This Row],[Growth Percentage]])^(Table2[[#Headers],[2028]]-YEAR(TODAY())) -> 74209691 | E7: =SUMIF('Database '!$A$11:$A$22,A7,'Database '!$G$11:$G$22)*(1+Table2[[#This Row],[Growth Percentage]])^(Table2[[#Headers],[2029]]-YEAR(TODAY())) -> 81630660 | F7: =SUMIF('Database '!$A$11:$A$22,A7,'Database '!$G$11:$G$22)*(1+Table2[[#This Row],[Growth Percentage]])^(Table2[[#Headers],[2030]]-YEAR(TODAY())) -> 89793726 | G7: =SUMIF('Database '!$A$11:$A$22,A7,'Database '!$G$11:$G$22)*(1+Table2[[#This Row],[Growth Percentage]])^(Table2[[#Headers],[2031]]-YEAR(TODAY())) -> 98773098 | H7: =SUMIF('Database '!$A$11:$A$22,A7,'Database '!$G$11:$G$22)*(1+Table2[[#This Row],[Growth Percentage]])^(Table2[[#Headers],[2032]]-YEAR(TODAY())) -> 1.0865041e+08 | I7: =SUMIF('Database '!$A$11:$A$22,A7,'Database '!$G$11:$G$22)*(1+Table2[[#This Row],[Growth Percentage]])^(Table2[[#Headers],[2033]]-YEAR(TODAY())) -> 1.1951545e+08 | J7: =SUMIF('Database '!$A$11:$A$22,A7,'Database '!$G$11:$G$22)*(1+Table2[[#This Row],[Growth Percentage]])^(Table2[[#Headers],[2034]]-YEAR(TODAY())) -> 1.3146699e+08 | K7: =SUMIF('Database '!$A$11:$A$22,A7,'Database '!$G$11:$G$22)*(1+Table2[[#This Row],[Growth Percentage]])^(Table2[[#Headers],[2035]]-YEAR(TODAY())) -> 1.4461369e+08 | L7: =SUMIF('Database '!$A$11:$A$22,A7,'Database '!$G$11:$G$22)*(1+Table2[[#This Row],[Growth Percentage]])^(Table2[[#Headers],[2036]]-YEAR(TODAY())) -> 1.5907506e+08
A8: ='Database '!$A$11 -> ADRO | B8: ='Database '!H28 -> 0.11 | C8: =SUMIF('Database '!$A$11:$A$22,A8,'Database '!$G$11:$G$22)*(1+Table2[[#This Row],[Growth Percentage]])^(Table2[[#Headers],[2027]]-YEAR(TODAY())) -> 68076658 | D8: =SUMIF('Database '!$A$11:$A$22,A8,'Database '!$G$11:$G$22)*(1+Table2[[#This Row],[Growth Percentage]])^(Table2[[#Headers],[2028]]-YEAR(TODAY())) -> 75565091 | E8: =SUMIF('Database '!$A$11:$A$22,A8,'Database '!$G$11:$G$22)*(1+Table2[[#This Row],[Growth Percentage]])^(Table2[[#Headers],[2029]]-YEAR(TODAY())) -> 83877251 | F8: =SUMIF('Database '!$A$11:$A$22,A8,'Database '!$G$11:$G$22)*(1+Table2[[#This Row],[Growth Percentage]])^(Table2[[#Headers],[2030]]-YEAR(TODAY())) -> 93103748 | G8: =SUMIF('Database '!$A$11:$A$22,A8,'Database '!$G$11:$G$22)*(1+Table2[[#This Row],[Growth Percentage]])^(Table2[[#Headers],[2031]]-YEAR(TODAY())) -> 1.0334516e+08 | H8: =SUMIF('Database '!$A$11:$A$22,A8,'Database '!$G$11:$G$22)*(1+Table2[[#This Row],[Growth Percentage]])^(Table2[[#Headers],[2032]]-YEAR(TODAY())) -> 1.1471313e+08 | I8: =SUMIF('Database '!$A$11:$A$22,A8,'Database '!$G$11:$G$22)*(1+Table2[[#This Row],[Growth Percentage]])^(Table2[[#Headers],[2033]]-YEAR(TODAY())) -> 1.2733157e+08 | J8: =SUMIF('Database '!$A$11:$A$22,A8,'Database '!$G$11:$G$22)*(1+Table2[[#This Row],[Growth Percentage]])^(Table2[[#Headers],[2034]]-YEAR(TODAY())) -> 1.4133805e+08 | K8: =SUMIF('Database '!$A$11:$A$22,A8,'Database '!$G$11:$G$22)*(1+Table2[[#This Row],[Growth Percentage]])^(Table2[[#Headers],[2035]]-YEAR(TODAY())) -> 1.5688523e+08 | L8: =SUMIF('Database '!$A$11:$A$22,A8,'Database '!$G$11:$G$22)*(1+Table2[[#This Row],[Growth Percentage]])^(Table2[[#Headers],[2036]]-YEAR(TODAY())) -> 1.7414261e+08
